Workbook
Name RFCList: fabi!$F$2:$F$1000
Name entradas: Tabla9[]
Name gastos: 'hoja de gastos'!$A$2:$E$98
Name ingresos: ingresos!$A$1:$I$60
Name salidas: Tabla9[]
Name salidas1: Tabla10[]
Name SegmentaciónDeDatos_mes: #N/A
Name SegmentaciónDeDatos_mes1: #N/A
Name tarifa: tabulador!$A$1:$D$7

Sheet DASHBOARD
A1: DASHBOARD — Concentrado CFDI
A2: Elige el contribuyente (RFC) y el mes; los indicadores y las gráficas se actualizan solos.
A4: Contribuyente (RFC):
A5: Mes: | C5: 1
A7: Ingresos (percepciones) | B7: Deducciones | C7: Balance (neto) | D7: Comprobantes | E7: Por revisar | J7: Percepciones | K7: =INDEX($B$12:$B$23,$C$5)
A8: =INDEX($B$12:$B$23,$C$5) | B8: =INDEX($C$12:$C$23,$C$5) | C8: =INDEX($D$12:$D$23,$C$5) | D8: =INDEX($E$12:$E$23,$C$5) | E8: =INDEX($F$12:$F$23,$C$5) | J8: Deducciones | K8: =INDEX($C$12:$C$23,$C$5)
A11: Mes | B11: Percepciones | C11: Deducciones | D11: Neto | E11: Comprobantes | F11: Por revisar | H11: #mes
A12: ENE | B12: =SUMPRODUCT((--(fabi!$R$2:$R$1000&""=TEXT($H12,"00")))*((($C$4="")+(fabi!$F$2:$F$1000=$C$4))>0)*fabi!$BF$2:$BF$1000) | C12: =SUMPRODUCT((--(fabi!$R$2:$R$1000&""=TEXT($H12,"00")))*((($C$4="")+(fabi!$F$2:$F$1000=$C$4))>0)*fabi!$CA$2:$CA$1000) | D12: =SUMPRODUCT((--(fabi!$R$2:$R$1000&""=TEXT($H12,"00")))*((($C$4="")+(fabi!$F$2:$F$1000=$C$4))>0)*fabi!$CD$2:$CD$1000) | E12: =SUMPRODUCT((--(fabi!$R$2:$R$1000&""=TEXT($H12,"00")))*((($C$4="")+(fabi!$F$2:$F$1000=$C$4))>0)) | F12: =SUMPRODUCT((--(fabi!$R$2:$R$1000&""=TEXT($H12,"00")))*((($C$4="")+(fabi!$F$2:$F$1000=$C$4))>0)*(--(fabi!$J$2:$J$1000<>"VIGENTE"))) | H12: 1
A13: FEB | B13: =SUMPRODUCT((--(fabi!$R$2:$R$1000&""=TEXT($H13,"00")))*((($C$4="")+(fabi!$F$2:$F$1000=$C$4))>0)*fabi!$BF$2:$BF$1000) | C13: =SUMPRODUCT((--(fabi!$R$2:$R$1000&""=TEXT($H13,"00")))*((($C$4="")+(fabi!$F$2:$F$1000=$C$4))>0)*fabi!$CA$2:$CA$1000) | D13: =SUMPRODUCT((--(fabi!$R$2:$R$1000&""=TEXT($H13,"00")))*((($C$4="")+(fabi!$F$2:$F$1000=$C$4))>0)*fabi!$CD$2:$CD$1000) | E13: =SUMPRODUCT((--(fabi!$R$2:$R$1000&""=TEXT($H13,"00")))*((($C$4="")+(fabi!$F$2:$F$1000=$C$4))>0)) | F13: =SUMPRODUCT((--(fabi!$R$2:$R$1000&""=TEXT($H13,"00")))*((($C$4="")+(fabi!$F$2:$F$1000=$C$4))>0)*(--(fabi!$J$2:$J$1000<>"VIGENTE"))) | H13: 2
A14: MZO | B14: =SUMPRODUCT((--(fabi!$R$2:$R$1000&""=TEXT($H14,"00")))*((($C$4="")+(fabi!$F$2:$F$1000=$C$4))>0)*fabi!$BF$2:$BF$1000) | C14: =SUMPRODUCT((--(fabi!$R$2:$R$1000&""=TEXT($H14,"00")))*((($C$4="")+(fabi!$F$2:$F$1000=$C$4))>0)*fabi!$CA$2:$CA$1000) | D14: =SUMPRODUCT((--(fabi!$R$2:$R$1000&""=TEXT($H14,"00")))*((($C$4="")+(fabi!$F$2:$F$1000=$C$4))>0)*fabi!$CD$2:$CD$1000) | E14: =SUMPRODUCT((--(fabi!$R$2:$R$1000&""=TEXT($H14,"00")))*((($C$4="")+(fabi!$F$2:$F$1000=$C$4))>0)) | F14: =SUMPRODUCT((--(fabi!$R$2:$R$1000&""=TEXT($H14,"00")))*((($C$4="")+(fabi!$F$2:$F$1000=$C$4))>0)*(--(fabi!$J$2:$J$1000<>"VIGENTE"))) | H14: 3
A15: ABR | B15: =SUMPRODUCT((--(fabi!$R$2:$R$1000&""=TEXT($H15,"00")))*((($C$4="")+(fabi!$F$2:$F$1000=$C$4))>0)*fabi!$BF$2:$BF$1000) | C15: =SUMPRODUCT((--(fabi!$R$2:$R$1000&""=TEXT($H15,"00")))*((($C$4="")+(fabi!$F$2:$F$1000=$C$4))>0)*fabi!$CA$2:$CA$1000) | D15: =SUMPRODUCT((--(fabi!$R$2:$R$1000&""=TEXT($H15,"00")))*((($C$4="")+(fabi!$F$2:$F$1000=$C$4))>0)*fabi!$CD$2:$CD$1000) | E15: =SUMPRODUCT((--(fabi!$R$2:$R$1000&""=TEXT($H15,"00")))*((($C$4="")+(fabi!$F$2:$F$1000=$C$4))>0)) | F15: =SUMPRODUCT((--(fabi!$R$2:$R$1000&""=TEXT($H15,"00")))*((($C$4="")+(fabi!$F$2:$F$1000=$C$4))>0)*(--(fabi!$J$2:$J$1000<>"VIGENTE"))) | H15: 4
A16: MAY | B16: =SUMPRODUCT((--(fabi!$R$2:$R$1000&""=TEXT($H16,"00")))*((($C$4="")+(fabi!$F$2:$F$1000=$C$4))>0)*fabi!$BF$2:$BF$1000) | C16: =SUMPRODUCT((--(fabi!$R$2:$R$1000&""=TEXT($H16,"00")))*((($C$4="")+(fabi!$F$2:$F$1000=$C$4))>0)*fabi!$CA$2:$CA$1000) | D16: =SUMPRODUCT((--(fabi!$R$2:$R$1000&""=TEXT($H16,"00")))*((($C$4="")+(fabi!$F$2:$F$1000=$C$4))>0)*fabi!$CD$2:$CD$1000) | E16: =SUMPRODUCT((--(fabi!$R$2:$R$1000&""=TEXT($H16,"00")))*((($C$4="")+(fabi!$F$2:$F$1000=$C$4))>0)) | F16: =SUMPRODUCT((--(fabi!$R$2:$R$1000&""=TEXT($H16,"00")))*((($C$4="")+(fabi!$F$2:$F$1000=$C$4))>0)*(--(fabi!$J$2:$J$1000<>"VIGENTE"))) | H16: 5
A17: JUN | B17: =SUMPRODUCT((--(fabi!$R$2:$R$1000&""=TEXT($H17,"00")))*((($C$4="")+(fabi!$F$2:$F$1000=$C$4))>0)*fabi!$BF$2:$BF$1000) | C17: =SUMPRODUCT((--(fabi!$R$2:$R$1000&""=TEXT($H17,"00")))*((($C$4="")+(fabi!$F$2:$F$1000=$C$4))>0)*fabi!$CA$2:$CA$1000) | D17: =SUMPRODUCT((--(fabi!$R$2:$R$1000&""=TEXT($H17,"00")))*((($C$4="")+(fabi!$F$2:$F$1000=$C$4))>0)*fabi!$CD$2:$CD$1000) | E17: =SUMPRODUCT((--(fabi!$R$2:$R$1000&""=TEXT($H17,"00")))*((($C$4="")+(fabi!$F$2:$F$1000=$C$4))>0)) | F17: =SUMPRODUCT((--(fabi!$R$2:$R$1000&""=TEXT($H17,"00")))*((($C$4="")+(fabi!$F$2:$F$1000=$C$4))>0)*(--(fabi!$J$2:$J$1000<>"VIGENTE"))) | H17: 6
A18: JUL | B18: =SUMPRODUCT((--(fabi!$R$2:$R$1000&""=TEXT($H18,"00")))*((($C$4="")+(fabi!$F$2:$F$1000=$C$4))>0)*fabi!$BF$2:$BF$1000) | C18: =SUMPRODUCT((--(fabi!$R$2:$R$1000&""=TEXT($H18,"00")))*((($C$4="")+(fabi!$F$2:$F$1000=$C$4))>0)*fabi!$CA$2:$CA$1000) | D18: =SUMPRODUCT((--(fabi!$R$2:$R$1000&""=TEXT($H18,"00")))*((($C$4="")+(fabi!$F$2:$F$1000=$C$4))>0)*fabi!$CD$2:$CD$1000) | E18: =SUMPRODUCT((--(fabi!$R$2:$R$1000&""=TEXT($H18,"00")))*((($C$4="")+(fabi!$F$2:$F$1000=$C$4))>0)) | F18: =SUMPRODUCT((--(fabi!$R$2:$R$1000&""=TEXT($H18,"00")))*((($C$4="")+(fabi!$F$2:$F$1000=$C$4))>0)*(--(fabi!$J$2:$J$1000<>"VIGENTE"))) | H18: 7
A19: AGO | B19: =SUMPRODUCT((--(fabi!$R$2:$R$1000&""=TEXT($H19,"00")))*((($C$4="")+(fabi!$F$2:$F$1000=$C$4))>0)*fabi!$BF$2:$BF$1000) | C19: =SUMPRODUCT((--(fabi!$R$2:$R$1000&""=TEXT($H19,"00")))*((($C$4="")+(fabi!$F$2:$F$1000=$C$4))>0)*fabi!$CA$2:$CA$1000) | D19: =SUMPRODUCT((--(fabi!$R$2:$R$1000&""=TEXT($H19,"00")))*((($C$4="")+(fabi!$F$2:$F$1000=$C$4))>0)*fabi!$CD$2:$CD$1000) | E19: =SUMPRODUCT((--(fabi!$R$2:$R$1000&""=TEXT($H19,"00")))*((($C$4="")+(fabi!$F$2:$F$1000=$C$4))>0)) | F19: =SUMPRODUCT((--(fabi!$R$2:$R$1000&""=TEXT($H19,"00")))*((($C$4="")+(fabi!$F$2:$F$1000=$C$4))>0)*(--(fabi!$J$2:$J$1000<>"VIGENTE"))) | H19: 8
A20: SEPT | B20: =SUMPRODUCT((--(fabi!$R$2:$R$1000&""=TEXT($H20,"00")))*((($C$4="")+(fabi!$F$2:$F$1000=$C$4))>0)*fabi!$BF$2:$BF$1000) | C20: =SUMPRODUCT((--(fabi!$R$2:$R$1000&""=TEXT($H20,"00")))*((($C$4="")+(fabi!$F$2:$F$1000=$C$4))>0)*fabi!$CA$2:$CA$1000) | D20: =SUMPRODUCT((--(fabi!$R$2:$R$1000&""=TEXT($H20,"00")))*((($C$4="")+(fabi!$F$2:$F$1000=$C$4))>0)*fabi!$CD$2:$CD$1000) | E20: =SUMPRODUCT((--(fabi!$R$2:$R$1000&""=TEXT($H20,"00")))*((($C$4="")+(fabi!$F$2:$F$1000=$C$4))>0)) | F20: =SUMPRODUCT((--(fabi!$R$2:$R$1000&""=TEXT($H20,"00")))*((($C$4="")+(fabi!$F$2:$F$1000=$C$4))>0)*(--(fabi!$J$2:$J$1000<>"VIGENTE"))) | H20: 9
A21: OCT | B21: =SUMPRODUCT((--(fabi!$R$2:$R$1000&""=TEXT($H21,"00")))*((($C$4="")+(fabi!$F$2:$F$1000=$C$4))>0)*fabi!$BF$2:$BF$1000) | C21: =SUMPRODUCT((--(fabi!$R$2:$R$1000&""=TEXT($H21,"00")))*((($C$4="")+(fabi!$F$2:$F$1000=$C$4))>0)*fabi!$CA$2:$CA$1000) | D21: =SUMPRODUCT((--(fabi!$R$2:$R$1000&""=TEXT($H21,"00")))*((($C$4="")+(fabi!$F$2:$F$1000=$C$4))>0)*fabi!$CD$2:$CD$1000) | E21: =SUMPRODUCT((--(fabi!$R$2:$R$1000&""=TEXT($H21,"00")))*((($C$4="")+(fabi!$F$2:$F$1000=$C$4))>0)) | F21: =SUMPRODUCT((--(fabi!$R$2:$R$1000&""=TEXT($H21,"00")))*((($C$4="")+(fabi!$F$2:$F$1000=$C$4))>0)*(--(fabi!$J$2:$J$1000<>"VIGENTE"))) | H21: 10
A22: NOV | B22: =SUMPRODUCT((--(fabi!$R$2:$R$1000&""=TEXT($H22,"00")))*((($C$4="")+(fabi!$F$2:$F$1000=$C$4))>0)*fabi!$BF$2:$BF$1000) | C22: =SUMPRODUCT((--(fabi!$R$2:$R$1000&""=TEXT($H22,"00")))*((($C$4="")+(fabi!$F$2:$F$1000=$C$4))>0)*fabi!$CA$2:$CA$1000) | D22: =SUMPRODUCT((--(fabi!$R$2:$R$1000&""=TEXT($H22,"00")))*((($C$4="")+(fabi!$F$2:$F$1000=$C$4))>0)*fabi!$CD$2:$CD$1000) | E22: =SUMPRODUCT((--(fabi!$R$2:$R$1000&""=TEXT($H22,"00")))*((($C$4="")+(fabi!$F$2:$F$1000=$C$4))>0)) | F22: =SUMPRODUCT((--(fabi!$R$2:$R$1000&""=TEXT($H22,"00")))*((($C$4="")+(fabi!$F$2:$F$1000=$C$4))>0)*(--(fabi!$J$2:$J$1000<>"VIGENTE"))) | H22: 11
A23: DIC | B23: =SUMPRODUCT((--(fabi!$R$2:$R$1000&""=TEXT($H23,"00")))*((($C$4="")+(fabi!$F$2:$F$1000=$C$4))>0)*fabi!$BF$2:$BF$1000) | C23: =SUMPRODUCT((--(fabi!$R$2:$R$1000&""=TEXT($H23,"00")))*((($C$4="")+(fabi!$F$2:$F$1000=$C$4))>0)*fabi!$CA$2:$CA$1000) | D23: =SUMPRODUCT((--(fabi!$R$2:$R$1000&""=TEXT($H23,"00")))*((($C$4="")+(fabi!$F$2:$F$1000=$C$4))>0)*fabi!$CD$2:$CD$1000) | E23: =SUMPRODUCT((--(fabi!$R$2:$R$1000&""=TEXT($H23,"00")))*((($C$4="")+(fabi!$F$2:$F$1000=$C$4))>0)) | F23: =SUMPRODUCT((--(fabi!$R$2:$R$1000&""=TEXT($H23,"00")))*((($C$4="")+(fabi!$F$2:$F$1000=$C$4))>0)*(--(fabi!$J$2:$J$1000<>"VIGENTE"))) | H23: 12
A24: TOTAL | B24: =SUM(B12:B23) | C24: =SUM(C12:C23) | D24: =SUM(D12:D23) | E24: =SUM(E12:E23) | F24: =SUM(F12:F23)

Sheet fabi
A1: N° | B1: UUID | C1: Fecha Emisión | D1: Fecha Timbrado | E1: Versión | F1: RFC Receptor | G1: Razón Social Emisor | H1: Régimen Fiscal | I1: PACCertificador | J1: Estatus | K1: Tipo de Comprobante | L1: Serie | M1: Folio | N1: Lugar Expedición | O1: Método de Pago | P1: Moneda | Q1: Tipo Nómina | R1: mes | S1: Fecha de Pago | T1: Total de Deducciones | U1: Total de Otros Pagos | V1: Registro Patronal (Emisor Nom) | W1: Curp (Receptor Nom) | X1: NumSeguridadSocial (Receptor Nom) | Y1: Antigüedad (Receptor Nom) | Z1: TipoJornada (Receptor Nom) | AA1: TipoRegimen (Receptor Nom) | AB1: NumEmpleado (Receptor Nom) | AC1: RiesgoPuesto (Receptor Nom) | AD1: PeriodicidadPago (Receptor Nom) | AE1: Banco (Receptor Nom) | AF1: CuentaBancaria (Receptor Nom) | AG1: SalarioBaseCotApor (Receptor Nom) | AH1: SalarioDiarioIntegrado (Receptor Nom) | AI1: 019 - HORAS EXTRAS DOBLES | Exento | AJ1: 010 - BONO PUNTUALIDAD | Gravado | AK1: 010 - BONO PUNTUALIDAD | Exento | AL1: 049 - BONO DE ASISTENCIA | Gravado | AM1: 049 - BONO DE ASISTENCIA | Exento | AN1: 003 - P T U Exento | Gravado | AO1: 003 - P T U Exento | Exento | AP1: 002 - AGUINALDO | Gravado | AQ1: 002 - AGUINALDO | Exento | AR1: 029 - Vales Despensa | Gravado | AS1: 029 - Vales Despensa | Exento | AT1: 020 - Prima Dominical | Gravado | AU1: 020 - Prima Dominical | Exento | AV1: 001 - SUELDO ORDINARIO | Gravado | AW1: 001 - SUELDO ORDINARIO | Exento | AX1: 028 - COMISIÓN COMPLEMENTARIA | Gravado | AY1: 028 - COMISIÓN COMPLEMENTARIA | Exento | AZ1: 005 - ApFondo Ahorro Empr | Gravado | BA1: 005 - ApFondo Ahorro Empr | Exento | BB1: 038 - Gratificaciones | Gravado | BC1: 038 - Gratificaciones | Exento | BD1: 021 - Prima Vac Exento Fijo | Gravado | BE1: 021 - Prima Vac Exento Fijo | Exento | BF1: PERCEPCIÓNES | BG1: 002 - Subsidio para el Empleo | BH1: 999 - Ajuste de Moneda | BI1: 007 - ISR Ajustado por Subsidio | BJ1: 004 - ISPT a Compensar | BK1: OTROS PAGOS - Subsidio Causado | BL1: OTROS PAGOS - Saldo Favor | BM1: OTROS PAGOS - Año | BN1: OTROS PAGOS - Remanente Saldo Favor | BO1: OTROS PAGOS | BP1: 002 - I S P T | BQ1: 010 - Apor Crédito INFONAVIT | BR1: 004 - Ajuste de Moneda | BS1: 007 - Pension Alimenticia | BT1: 011 - Pago de abonos FONACOT | BU1: 001 - Aportación trabaj IMSS | BV1: 101 - ISPT A CARGO | BW1: 107 - Ajuste al Subsidio Causado | BX1: 018 - Ahorro a la Vista SCYF | BY1: 021 - Aport IMSS trabajad | BZ1: 009 - Prestamos provenientes del Fondo Nacional de la Vivienda para los Trabajadores | CA1: DEDUCCIONES | CB1: 02 - Días de Incapacidad: | CC1: INCAPACIDADES | CD1: NETO | CE1: NETO
A2: 268 | C2: 25/01/2023 10:50:10 p. m. | E2: 4.0 | H2: 623-Opcional para Grupos de Sociedades | I2: INT020124V62 | J2: VIGENTE | K2: Nómina | L2: CFDI | O2: PUE-Pago en una sola exhibición | P2: Peso Mexicano | Q2: O-Nómina ordinaria | R2: =MID(S2,4,2) -> 01 | S2: 25/01/2023 12:00:00 a. m. | T2: 1558.89 | U2: 0.21 | Y2: P78W | Z2: 01-Diurna | AA2: 02-Sueldos (Incluye ingresos señalados en la fracción I del artículo 94 de LISR) | AC2: 3-Clase III | AD2: 02-Semanal | AE2: 127 | AG2: 4338.46 | AH2: 594.27 | AI2: 0 | AJ2: 145.21 | AK2: 0 | AL2: 145.21 | AM2: 0 | AN2: 0 | AO2: 0 | AP2: 0 | AQ2: 0 | AR2: 0 | AS2: 0 | AT2: 0 | AU2: 51.86 | AV2: 1452.08 | AW2: 0 | AX2: 2834.52 | AY2: 0 | AZ2: 0 | BA2: 0 | BB2: 174.25 | BC2: 0 | BD2: 0 | BE2: 0 | BF2: 4803.13 | BG2: 0 | BH2: 0.21 | BI2: 0 | BJ2: 0 | BK2: 0 | BO2: 0.21 | BP2: 630.77 | BQ2: 605.76 | BR2: 215 | BS2: 0 | BT2: 0 | BU2: 107.36 | BV2: 0 | BW2: 0 | BX2: 0 | BY2: 0 | BZ2: 0 | CA2: 1558.89 | CB2: 0 | CC2: 0 | CD2: 3244.45
A3: 271 | C3: 18/01/2023 08:47:12 p. m. | E3: 4.0 | H3: 623-Opcional para Grupos de Sociedades | I3: INT020124V62 | J3: VIGENTE | K3: Nómina | L3: CFDI | O3: PUE-Pago en una sola exhibición | P3: Peso Mexicano | Q3: O-Nómina ordinaria | R3: =MID(S3,4,2) -> 01 | S3: 18/01/2023 12:00:00 a. m. | T3: 1391.81 | U3: 0 | Y3: P77W | Z3: 01-Diurna | AA3: 02-Sueldos (Incluye ingresos señalados en la fracción I del artículo 94 de LISR) | AC3: 3-Clase III | AD3: 02-Semanal | AE3: 127 | AG3: 3556.23 | AH3: 594.27 | AI3: 0 | AJ3: 145.21 | AK3: 0 | AL3: 145.21 | AM3: 0 | AN3: 0 | AO3: 0 | AP3: 0 | AQ3: 0 | AR3: 0 | AS3: 0 | AT3: 0 | AU3: 51.86 | AV3: 1452.08 | AW3: 0 | AX3: 2052.29 | AY3: 0 | AZ3: 0 | BA3: 0 | BB3: 174.25 | BC3: 0 | BD3: 0 | BE3: 0 | BF3: 4020.9 | BG3: 0 | BH3: 0 | BI3: 0 | BJ3: 0 | BK3: 0 | BO3: 0 | BP3: 463.69 | BQ3: 605.76 | BR3: 215 | BS3: 0 | BT3: 0 | BU3: 107.36 | BV3: 0 | BW3: 0 | BX3: 0 | BY3: 0 | BZ3: 0 | CA3: 1391.81 | CB3: 0 | CC3: 0 | CD3: 2629.09
A4: 273 | C4: 11/01/2023 10:51:06 p. m. | E4: 4.0 | H4: 623-Opcional para Grupos de Sociedades | I4: INT020124V62 | J4: VIGENTE | K4: Nómina | L4: CFDI | O4: PUE-Pago en una sola exhibición | P4: Peso Mexicano | Q4: O-Nómina ordinaria | R4: =MID(S4,4,2) -> 01 | S4: 11/01/2023 12:00:00 a. m. | T4: 1349.4 | U4: 159.29 | Y4: P76W | Z4: 01-Diurna | AA4: 02-Sueldos (Incluye ingresos señalados en la fracción I del artículo 94 de LISR) | AC4: 3-Clase III | AD4: 02-Semanal | AE4: 127 | AG4: 3356.78 | AH4: 594.27 | AI4: 0 | AJ4: 145.21 | AK4: 0 | AL4: 145.21 | AM4: 0 | AN4: 0 | AO4: 0 | AP4: 0 | AQ4: 0 | AR4: 0 | AS4: 0 | AT4: 0 | AU4: 51.86 | AV4: 1452.08 | AW4: 0 | AX4: 1852.84 | AY4: 0 | AZ4: 0 | BA4: 0 | BB4: 174.25 | BC4: 0 | BD4: 0 | BE4: 0 | BF4: 3821.45 | BG4: 0 | BH4: 0 | BI4: 0 | BJ4: 159.29 | BK4: 0 | BL4: 159.29 | BM4: 2022 | BN4: 0 | BO4: 159.29 | BP4: 421.09 | BQ4: 605.95 | BR4: 215 | BS4: 0 | BT4: 0 | BU4: 107.36 | BV4: 0 | BW4: 0 | BX4: 0 | BY4: 0 | BZ4: 0 | CA4: 1349.4 | CB4: 0 | CC4: 0 | CD4: 2631.34
A5: 274 | C5: 04/01/2023 11:39:39 p. m. | E5: 4.0 | H5: 623-Opcional para Grupos de Sociedades | I5: INT020124V62 | J5: VIGENTE | K5: Nómina | L5: CFDI | O5: PUE-Pago en una sola exhibición | P5: Peso Mexicano | Q5: O-Nómina ordinaria | R5: =MID(S5,4,2) -> 01 | S5: 04/01/2023 12:00:00 a. m. | T5: 1338.53 | U5: 0 | Y5: P75W | Z5: 01-Diurna | AA5: 02-Sueldos (Incluye ingresos señalados en la fracción I del artículo 94 de LISR) | AC5: 3-Clase III | AD5: 02-Semanal | AE5: 127 | AG5: 3556.16 | AH5: 594.27 | AI5: 0 | AJ5: 145.21 | AK5: 0 | AL5: 145.21 | AM5: 0 | AN5: 0 | AO5: 0 | AP5: 0 | AQ5: 0 | AR5: 0 | AS5: 0 | AT5: 0 | AU5: 0 | AV5: 1659.52 | AW5: 207.44 | AX5: 1689.2 | AY5: 0 | AZ5: 0 | BA5: 0 | BB5: 174.25 | BC5: 0 | BD5: 0 | BE5: 0 | BF5: 4020.83 | BG5: 0 | BH5: 0 | BI5: 0 | BJ5: 0 | BK5: 0 | BO5: 0 | BP5: 430.44 | BQ5: 603.92 | BR5: 215 | BS5: 0 | BT5: 0 | BU5: 89.17 | BV5: 0 | BW5: 0 | BX5: 0 | BY5: 0 | BZ5: 0 | CA5: 1338.53 | CB5: 0 | CC5: 0 | CD5: 2682.3

Sheet ingresos
G1: REGIMEN SUELDOS Y SALARIOS E ING ASIMILADOS | I1: B
G2: 605 | I2: 248.93
H4: PAGO PROVISIONAL MENSUAL
D5: =IFERROR(+D7/I2,0) | H5: 1 | I5: TOTAL
A6: RFC | B6: CURP | C6: NSS | D6: SDI | E6: SBC | F6: INICIO RL | G6: CONCEPTOS | H6: ENE
A7: =+fabi!$F$2 | B7: =+fabi!$W$2 | C7: =+fabi!$X$2 | D7: =+fabi!$AH$2 | E7: =+fabi!$AG$2 | F7: 19/07/2021 12:00:00 a. m. | G7: FABIOLA PONCE GARCIA | H7: =SUM(H8:H20) -> 16666.31 | I7: =SUM(I8:I20) -> 16666.31
G8: puntualidad gravado | H8: =SUMIF(fabi!$R:$R,ingresos!H$5,fabi!AJ:$AJ) -> 580.84 | I8: =SUM(H8:H8) -> 580.84
G9: asistencia gravado | H9: =SUMIF(fabi!$R:$R,ingresos!H$5,fabi!AL:$AL) -> 580.84 | I9: =SUM(H9:H9) -> 580.84
G10: ptu gravado | H10: =SUMIF(fabi!$R:$R,ingresos!H$5,fabi!AN:$AN) -> 0 | I10: =SUM(H10:H10) -> 0
G11: ptu exento | H11: =SUMIF(fabi!$R:$R,ingresos!H$5,fabi!AO:$AO) -> 0 | I11: =SUM(H11:H11) -> 0
G12: aguinaldo gravado | H12: =SUMIF(fabi!$R:$R,ingresos!H$5,fabi!AP:$AP) -> 0 | I12: =SUM(H12:H12) -> 0
G13: aguinaldo exento | H13: =SUMIF(fabi!$R:$R,ingresos!H$5,fabi!AQ:$AQ) -> 0 | I13: =SUM(H13:H13) -> 0
G14: prima dominical exento | H14: =SUMIF(fabi!$R:$R,ingresos!H$5,fabi!AU:$AU) -> 155.58 | I14: =SUM(H14:H14) -> 155.58
G15: sueldo ordinario gravado | H15: =SUMIF(fabi!$R:$R,ingresos!H$5,fabi!AV:$AV) -> 6015.76 | I15: =SUM(H15:H15) -> 6015.76
G16: sueldo ordinario exento | H16: =SUMIF(fabi!$R:$R,ingresos!H$5,fabi!AW:$AW) -> 207.44 | I16: =SUM(H16:H16) -> 207.44
G17: comisiones gravadas | H17: =SUMIF(fabi!$R:$R,ingresos!H$5,fabi!AX:$AX) -> 8428.85 | I17: =SUM(H17:H17) -> 8428.85
G18: gratificaciones gravada | H18: =SUMIF(fabi!$R:$R,ingresos!H$5,fabi!BB:$BB) -> 697 | I18: =SUM(H18:H18) -> 697
G19: prima vac gravada | H19: =SUMIF(fabi!$R:$R,ingresos!H$5,fabi!BD:$BD) -> 0 | I19: =SUM(H19:H19) -> 0
G20: prima vac exenta | H20: =SUMIF(fabi!$R:$R,ingresos!H$5,fabi!BE:$BE) -> 0 | I20: =SUM(H20:H20) -> 0
G21: PERCEPCIONES | H21: =SUMIF(fabi!$R:$R,ingresos!H$5,fabi!BF:$BF) -> 16666.31 | I21: =SUM(H21:H21) -> 16666.31
G22: INGRESOS COBRADOS DEL MES | H22: =+H7 -> 16666.31 | I22: =SUM(H22:H22) -> 16666.31
G23: =+G7 -> FABIOLA PONCE GARCIA | H23: =SUM(H24:H27) -> 4778.63 | I23: =SUM(I24:I27) -> 4778.63
G24: IMSS | H24: =SUMIF(fabi!$R:$R,ingresos!H$5,fabi!BU:$BU) -> 411.25 | I24: =SUM(H24:H24) -> 411.25
G25: INFONAVIT | H25: =SUMIF(fabi!$R:$R,ingresos!H$5,fabi!BQ:$BQ) -> 2421.39 | I25: =SUM(H25:H25) -> 2421.39
G26: ISPT | H26: =SUMIF(fabi!$R:$R,ingresos!H$5,fabi!BP:$BP) -> 1945.99 | I26: =SUM(H26:H26) -> 1945.99
G27: FONDO AHORRO | H27: =SUMIF(fabi!$R:$R,ingresos!H$5,fabi!BX:$BX) -> 0 | I27: =SUM(H27:H27) -> 0
G28: OTRAS DEDUCCIONES | H28: =+H29-H23 -> 860 | I28: =SUM(H28:H28) -> 860
G29: DEDUCCIONES | H29: =SUMIF(fabi!$R:$R,ingresos!H$5,fabi!CA:$CA) -> 5638.63 | I29: =SUM(H29:H29) -> 5638.63
G30: TOTAL DEDUCCIONES | H30: =SUM(H24:H28) -> 5638.63 | I30: =SUM(I24:I28) -> 5638.63
G32: UTIL O PERD FISC DEL MES | H32: =+H$22-H$30 -> 11027.68 | I32: =SUM(H32:H32) -> 11027.68
G33: =+G23 -> FABIOLA PONCE GARCIA | H33: =+H7-H30 -> 11027.68 | I33: =SUM(H33:H33) -> 11027.68
G34: limite inferior | H34: =IFERROR(VLOOKUP(H32,tarifa,1),0)
G35: limite inferior | H35: =IFERROR(VLOOKUP(H34,tarifa,1),0)
G36: excedente lim.inferior | H36: =+H32-H34+H35 -> 11027.68
G37: tasa de ISR % | H37: =IFERROR(VLOOKUP(H32,tarifa,4),0)
H38: =IFERROR(+H37/100,0)
G39: impuesto marginal | H39: =+H36*H38 -> 110.2768
G40: cuota fija | H40: =IFERROR(VLOOKUP(H32,tarifa,3),0)
G41: TOTAL ISR | H41: =+H39+H40 -> 110.2768 | I41: =SUM(H41:H41) -> 110.2768
G42: RETENCION DE ISR | I42: =SUM(H42:H42) -> 0
...

Sheet hoja de gastos
B2: GASTOS FIJOS | D2: BASICOS (indispensables para vivir dignamente)
B3: concepto | D3: 1
B4: servicios | D4: ene | E4: total
B5: porcentajes | D5: =IFERROR(+D45/ingresos!H32*100,0)
B6: renta
B7: hipoteca
B8: cespt(agua) | C8: 6 | D8: 885 | E8: =SUM(D8) -> 885
B9: luz(cfe) | C9: 2 | D9: 368.04 | E9: =SUM(D9:D9) -> 368.04
B10: manto privada | C10: 7 | D10: 110 | E10: =SUM(D10:D10) -> 110
B11: gas | C11: 31 | D11: =100*4 -> 400 | E11: =SUM(D11:D11) -> 400
B12: internet IZZI | C12: 4 | D12: 390 | E12: =SUM(D12:D12) -> 390
B13: recargas telcel | D13: =50+50+20+50+50 -> 220 | E13: =SUM(D13:D13) -> 220
B14: predial | D14: 0 | E14: =SUM(D14:D14) -> 0
B15: salud | D15: 0 | E15: =SUM(D15:D15) -> 0
B16: TOTAL1 | D16: =SUM(D6:D15) -> 2373.04 | E16: =SUM(E6:E15) -> 2373.04
A17: alimentos | B17: alimentos
B18: florido: | D18: =SUM(D19:D25) -> 6433.21 | E18: =SUM(D18:D18) -> 6433.21
B19: despensa | C19: 30 | D19: 529.04 | E19: =SUM(D19:D19) -> 529.04
B20: despensa | C20: 26 | D20: 376.66 | E20: =SUM(D20:D20) -> 376.66
B21: despensa | C21: 20 | D21: 2029.88 | E21: =SUM(D21:D21) -> 2029.88
B22: despensa | C22: 13 | D22: 2186.71 | E22: =SUM(D22:D22) -> 2186.71
B23: despensa | C23: 12 | D23: 530.63 | E23: =SUM(D23:D23) -> 530.63
B24: despensa | C24: 5 | D24: 349.57 | E24: =SUM(D24:D24) -> 349.57
B25: despensa | C25: 3 | D25: 430.72 | E25: =SUM(D25:D25) -> 430.72
B26: despensa
B27: despensa
B28: mercados y congelados | C28: 12 | D28: 167.86 | E28: =SUM(D28:D28) -> 167.86
B29: abarrotes pp | E29: =SUM(D29:D29) -> 0
B30: oxxo
B31: carrito de verduras | E31: =SUM(D31:D31) -> 0
B32: el semillero | E32: =SUM(D32:D32) -> 0
B33: calimax
B34: tortillas,pan,bonpane | E34: =SUM(D34:D34) -> 0
B35: TOTAL2 | D35: =SUM(D19:D34) -> 6601.07 | E35: =SUM(E18:E34) -> 13034.28
A36: transportes | B36: transporte
B37: pasajes1 | C37: 31 | D37: =18*4*2*4 -> 576 | E37: =SUM(D37:D37) -> 576
B38: pasaje2 | C38: 31 | D38: =45*2*5 -> 450 | E38: =SUM(D38:D38) -> 450
B39: TOTAL3 | D39: =SUM(D37:D38) -> 1026 | E39: =SUM(E37:E38) -> 1026
B40: salud y educación
A41: salud | B41: escuela de hijos,impresiones
...

Sheet presupuesto
C2: Presupuesto Mensual
C3: Sólo llena los campos que apliquen a tus finanzas | I3: Mes: | K3: Enero | M3: Enero
M4: Febrero
B5: DINERO QUE TIENES MENSUALMENTE | M5: Abril
C6: Concepto | E6: Monto $ | I6: Concepto | K6: Monto $ | M6: Mayo
B7: Salario 1 | E7: =+ingresos!H33 -> 11027.68 | G7: Negocio propio | K7: 0 | M7: Junio
B8: Salario 2 | E8: 0 | G8: Otros Ingresos 1 | K8: 0 | M8: Julio
B9: Honorarios | E9: 0 | G9: Otros Ingresos 2 | K9: 0 | M9: Agosto
M10: Septiembre
B11: Total de ingresos | E11: =+E7+E8+E9+K7+K8+K9 -> 11027.68 | M11: Octubre
B12: GASTOS FIJOS INDISPENSABLE (no puedes prescindir de ellos) BASICOS | M12: Noviembre
B13: Concepto / Gasto | C13: Monto | E13: Concepto / Gasto | F13: Monto | I13: Concepto / Gasto | K13: Monto | M13: Diciembre
B15: Casa | E15: Automóvil | I15: Salud
B16: Renta | C16: =+'hoja de gastos'!D6 -> 0 | E16: Gasolina | G16: 0 | I16: Seguro de auto | K16: 0
B17: Otros (hipoteca) | C17: =+'hoja de gastos'!D7 -> 0 | E17: Transporte público (iglesia) | G17: =+'hoja de gastos'!D37 -> 576 | I17: Seguro de casa | K17: 0
B18: Servicios | E18: Otros | G18: 0 | I18: Seguro de vida | K18: 0
B19: Gas | C19: =+'hoja de gastos'!D11 -> 400 | E19: Personales | I19: Seguro médico
B20: Luz | C20: =+'hoja de gastos'!D9 -> 368.04 | E20: Higiene personal | G20: 0 | I20: Mascotas
B21: Teléfono | C21: =+'hoja de gastos'!D13 -> 220 | E21: Recargas cel o plan | I21: Alimento | K21: 0
B22: Internet | C22: =+'hoja de gastos'!D12 -> 390 | E22: Iglesia (contribución) | G22: 0 | I22: Otros | K22: 0
B23: Mantto privada | C23: =+'hoja de gastos'!D10 -> 110 | E23: Otros | G23: 0 | I23: Deudas
B24: Agua | C24: =+'hoja de gastos'!D8 -> 885 | E24: Hijos | I24: Prestamo personal | K24: =+'hoja de gastos'!D90
B25: Predial | C25: =+'hoja de gastos'!D14 -> 0 | E25: Colegiaturas | G25: 0 | I25: Tarjeta de crédito1 | K25: =+'hoja de gastos'!D81
B26: Otros (gtos) | C26: =+'hoja de gastos'!D15 -> 0 | E26: Gasto diario (transporte publico) | G26: =+'hoja de gastos'!D38 -> 450 | I26: Tarjeta de crédito2 | K26: =+'hoja de gastos'!D80
B27: Alimentos | E27: Celular | G27: 0 | I27: Crédito automotriz | K27: 0
B28: Supermercado (despensa) | C28: =+'hoja de gastos'!D35 -> 6601.07 | E28: Clases extra | G28: 0 | I28: Préstamo de consumo | K28: 0
B29: Mercado (rudy) | E29: Gastos medicos (salud) | G29: =+'hoja de gastos'!D15 -> 0 | I29: Otros | K29: 0 | L29: =SUM(K24:K29) -> #REF! | M29: =IFERROR(+L29/E11,0)
A30: =IFERROR(+D30/E11,0) | B30: Total Gastos Fijos | D30: =+C16+C17+C19+C20+C21+C22+C23+C24+C25+C26+C28+C29+G16+G17+G18+G20+G21+G22+G23+G25+G26+G27+G28+G29+K16+K17+K18+K19+K21+K22 -> 10000.11
B31: GASTOS VARIABLES QUE SÓLO HACES DE VEZ EN CUANDO LUJOS
B33: Concepto / Gasto | C33: Dinero | E33: Concepto / Gasto | F33: Dinero | I33: Concepto / Gasto | K33: Recurso
B35: mantenimientos Casa | E35: LUJOS (Entretenimiento) | I35: LUJOS (Personales)
B36: Reparaciones | C36: 0 | E36: Cine / Teatro | G36: 0 | I36: Ropa | K36: 0
B37: Productos de limpieza | C37: 0 | E37: Restaurantes(comidas) | G37: =+'hoja de gastos'!D56 -> 452 | I37: Salud (Medicina) | K37: 0
B38: Otros(electronica/linea bca) | C38: 0 | E38: Fiesta / Bar | G38: 0 | I38: Cosméticos | K38: 0
B39: Automóvil | E39: Otros(cumpleaños) | G39: 0 | I39: Tintorería | K39: 0
B40: Mantenimiento | C40: 0 | E40: Otros (eventos Iglesia | G40: 0 | I40: otros | K40: =+'hoja de gastos'!D68 -> 1061.3
B41: Estacionamiento | C41: 0 | E41: Otros | G41: 0 | I41: Hijos y Emprendimiento
B42: Otros | C42: 0 | E42: LUJOS Viajes | I42: Libros / Útiles | K42: 0
B43: LUJOS Mascotas | E43: Hotel | G43: 0 | I43: Juguetes / Juegos | K43: 0
B44: Veterinario | C44: 0 | E44: Transporte | G44: 0 | I44: Otros | K44: 0
...

Sheet REGLA DE ORO
B1: REGLA DE ORO PARA CLASIFICACION DE GASTOS
H2: ene
B3: REGLA DE ORO: | C3: CORRECTO | D3: CORRECTO | E3: REAL | F3: REAL | G3: diferencia | H3: diferencia
C4: montos | D4: % | E4: montos | F4: % | G4: % | H4: montos
B5: BASICOS | C5: =+C11*0.5 -> 5513.84 | D5: =IFERROR(+C5/C11,0) | E5: =+'hoja de gastos'!D45 -> 10000.11 | F5: =IFERROR(+E5/C11,0) | G5: =+D5-F5 -> -0.40681902 | H5: =+C5-E5 -> -4486.27
B6: LUJOS | C6: =+C11*0.2 -> 2205.536 | D6: =IFERROR(+C6/C11,0) | E6: =+'hoja de gastos'!D75 -> 1513.3 | F6: =IFERROR(+E6/C11,0) | G6: =+D6-F6 -> 0.062772587 | H6: =+C6-E6 -> 692.236
B7: AHORRO | C7: =+C11*0.3 -> 3308.304 | D7: =IFERROR(+C7/C11,0) | E7: =+'hoja de gastos'!D94 -> 3829 | F7: =IFERROR(+E7/C11,0) | G7: =+D7-F7 -> -0.047217184 | H7: =+C7-E7 -> -520.696
B8: 20% DEUDAS (META 1) | C8: =+C11*0.2 -> 2205.536 | D8: =IFERROR(+C8/C13,0)
B9: 5% META 2 | C9: =+C11*0.05 -> 551.384
B10: 5% META 3 | C10: =+C11*0.05 -> 551.384
C11: =+ingresos!H32 -> 11027.68 | D11: =SUM(D5:D7) -> 1 | E11: =+E5+E6+E7 -> 15342.41 | F11: =SUM(F5:F7) -> 1.3912636 | G11: =SUM(G5:G10) -> -0.39126362 | H11: =+H5+H6+H7 -> -4314.73
C13: =+C5+C6+C7 -> 11027.68
B16: FONDO DE EMERGENCIA
B17: IDEAL 3 meses | C17: =+C5*3 -> 16541.52
B18: AMBICIOSO 6 meses | C18: =+C5*6 -> 33083.04

Sheet detalle
B1: entradas y salidas
B4: entradas | G4: salidas
D5: total | E5: =SUM(E8:E64) -> 11187.18 | I5: total | J5: =SUM(J8:J31) -> 15342.41
B7: fecha | C7: mes | D7: concepto | E7: valor | G7: fecha | H7: mes | I7: concepto | J7: valor
B8: 45657 | C8: =IFERROR(IF(B8="","",MONTH(B8)),"") | D8: salario | G8: 45322 | H8: 1 | I8: =+'hoja de gastos'!$B$4 -> servicios | J8: =+'hoja de gastos'!D$16 -> 2373.04
C9: =IFERROR(IF(B9="","",MONTH(B9)),"") | D9: =+D8 -> salario | G9: 45322 | H9: =+H8 -> 1 | I9: =+'hoja de gastos'!A17 -> alimentos | J9: =+'hoja de gastos'!D$35 -> 6601.07
C10: =IFERROR(IF(B10="","",MONTH(B10)),"") | D10: =+D9 -> salario | G10: 45322 | H10: =+H9 -> 1 | I10: =+'hoja de gastos'!A36 -> transportes | J10: =+'hoja de gastos'!D$39 -> 1026
C11: =IFERROR(IF(B11="","",MONTH(B11)),"") | D11: =+D10 -> salario | G11: 45322 | H11: =+H10 -> 1 | I11: =+'hoja de gastos'!A41 -> salud | J11: =+'hoja de gastos'!D$44 -> 0
C12: =IFERROR(IF(B12="","",MONTH(B12)),"") | D12: =+D11 -> salario | G12: 45322 | H12: 1 | I12: =+'hoja de gastos'!A48 -> recreacion | J12: =+'hoja de gastos'!D$56 -> 452
B13: 45626 | C13: =IFERROR(IF(B13="","",MONTH(B13)),"") | D13: =+D12 -> salario | G13: 45322 | H13: 1 | I13: =+'hoja de gastos'!A57 -> g personales | J13: =+'hoja de gastos'!D$68 -> 1061.3
C14: =IFERROR(IF(B14="","",MONTH(B14)),"") | D14: =+D13 -> salario | G14: 45322 | H14: 1 | I14: =+'hoja de gastos'!A69 -> cumpleaños | J14: =+'hoja de gastos'!D$74 -> 0
C15: =IFERROR(IF(B15="","",MONTH(B15)),"") | D15: =+D14 -> salario | G15: 45351 | H15: 2 | I15: =+I8 -> servicios
C16: =IFERROR(IF(B16="","",MONTH(B16)),"") | D16: =+D15 -> salario | G16: 45351 | H16: 2 | I16: =+I9 -> alimentos
C17: =IFERROR(IF(B17="","",MONTH(B17)),"") | D17: =+D16 -> salario | G17: 45351 | H17: 2 | I17: =+I10 -> transportes
C18: =IFERROR(IF(B18="","",MONTH(B18)),"") | D18: salario | G18: 45351 | H18: 2 | I18: =+I11 -> salud
B19: 45595 | C19: =IFERROR(IF(B19="","",MONTH(B19)),"") | D19: salario | G19: 45351 | H19: 2 | I19: =+I12 -> recreacion
C20: =IFERROR(IF(B20="","",MONTH(B20)),"") | D20: salario | G20: 45351 | H20: 2 | I20: =+I13 -> g personales
C21: =IFERROR(IF(B21="","",MONTH(B21)),"") | D21: salario | G21: 45351 | H21: 2 | I21: =+I14 -> cumpleaños
C22: =IFERROR(IF(B22="","",MONTH(B22)),"") | D22: salario | G22: 45382 | H22: 3 | I22: servicios
B23: 45565 | C23: =IFERROR(IF(B23="","",MONTH(B23)),"") | D23: salario | G23: 45382 | H23: 3 | I23: alimentos
C24: =IFERROR(IF(B24="","",MONTH(B24)),"") | D24: salario | G24: 45382 | H24: 3 | I24: transportes
C25: =IFERROR(IF(B25="","",MONTH(B25)),"") | D25: salario | G25: 45382 | H25: 3 | I25: salud
C26: =IFERROR(IF(B26="","",MONTH(B26)),"") | D26: salario | G26: 45382 | H26: 3 | I26: recreacion
B27: 45534 | C27: =IFERROR(IF(B27="","",MONTH(B27)),"") | D27: salario | G27: 45382 | H27: 3 | I27: g personales
C28: =IFERROR(IF(B28="","",MONTH(B28)),"") | D28: salario | G28: 45382 | H28: 3 | I28: cumpleaños
C29: =IFERROR(IF(B29="","",MONTH(B29)),"") | D29: salario | G29: 45322 | H29: 1 | I29: =+'hoja de gastos'!A94 -> pago deuda | J29: =+'hoja de gastos'!D$94 -> 3829
C30: =IFERROR(IF(B30="","",MONTH(B30)),"") | D30: salario | G30: 45351 | H30: 2 | I30: pago deuda
C31: =IFERROR(IF(B31="","",MONTH(B31)),"") | D31: salario | G31: 45382 | H31: 3 | I31: pago deuda
B32: 45503 | C32: =IFERROR(IF(B32="","",MONTH(B32)),"") | D32: salario
C33: =IFERROR(IF(B33="","",MONTH(B33)),"") | D33: salario
C34: =IFERROR(IF(B34="","",MONTH(B34)),"") | D34: salario
C35: =IFERROR(IF(B35="","",MONTH(B35)),"") | D35: salario
B36: 45473 | C36: =IFERROR(IF(B36="","",MONTH(B36)),"") | D36: salario
C37: =IFERROR(IF(B37="","",MONTH(B37)),"") | D37: salario
C38: =IFERROR(IF(B38="","",MONTH(B38)),"") | D38: salario
C39: =IFERROR(IF(B39="","",MONTH(B39)),"") | D39: salario
B40: 45442 | C40: =IFERROR(IF(B40="","",MONTH(B40)),"") | D40: salario
C41: =IFERROR(IF(B41="","",MONTH(B41)),"") | D41: salario
C42: =IFERROR(IF(B42="","",MONTH(B42)),"") | D42: salario
C43: =IFERROR(IF(B43="","",MONTH(B43)),"") | D43: salario
...

Sheet concentrado
B2: CONCEPTO | C2: 1 | D2: 2 | E2: 3 | F2: 4 | G2: 5 | H2: 6 | I2: 7 | J2: 8 | K2: 9 | L2: 10 | M2: 11 | N2: 12 | O2: TOTAL
C3: ENE | D3: FEB | E3: MZO | F3: ABR | G3: MAY | H3: JUN | I3: JUL | J3: AGO | K3: SEPT | L3: OCT | M3: NOV | N3: DIC
B4: ingresos | C4: =SUMIF(detalle!$C$8:$C$94,concentrado!C$2,detalle!$E$8:$E$94) | D4: =SUMIF(detalle!$C$8:$C$94,concentrado!D$2,detalle!$E$8:$E$94) | E4: =SUMIF(detalle!$C$8:$C$94,concentrado!E$2,detalle!$E$8:$E$94) | F4: =SUMIF(detalle!$C$8:$C$94,concentrado!F$2,detalle!$E$8:$E$94) | G4: =SUMIF(detalle!$C$8:$C$94,concentrado!G$2,detalle!$E$8:$E$94) | H4: =SUMIF(detalle!$C$8:$C$94,concentrado!H$2,detalle!$E$8:$E$94) | I4: =SUMIF(detalle!$C$8:$C$94,concentrado!I$2,detalle!$E$8:$E$94) | J4: =SUMIF(detalle!$C$8:$C$94,concentrado!J$2,detalle!$E$8:$E$94) | ... N4: =SUMIF(detalle!$C$8:$C$94,concentrado!N$2,detalle!$E$8:$E$94) | O4: =SUM(C4:N4) -> 11187.18
B5: egresos | C5: =SUMIF(detalle!$H$8:$H$50,concentrado!C$2,detalle!$J$8:$J$50) | D5: =SUMIF(detalle!$H$8:$H$50,concentrado!D$2,detalle!$J$8:$J$50) | E5: =SUMIF(detalle!$H$8:$H$50,concentrado!E$2,detalle!$J$8:$J$50) | F5: =SUMIF(detalle!$H$8:$H$50,concentrado!F$2,detalle!$J$8:$J$50) | G5: =SUMIF(detalle!$H$8:$H$50,concentrado!G$2,detalle!$J$8:$J$50) | H5: =SUMIF(detalle!$H$8:$H$50,concentrado!H$2,detalle!$J$8:$J$50) | I5: =SUMIF(detalle!$H$8:$H$50,concentrado!I$2,detalle!$J$8:$J$50) | J5: =SUMIF(detalle!$H$8:$H$50,concentrado!J$2,detalle!$J$8:$J$50) | ... N5: =SUMIF(detalle!$H$8:$H$50,concentrado!N$2,detalle!$J$8:$J$50) | O5: =SUM(C5:N5) -> 15342.41
B6: saldo | C6: =+C4-C5 -> -4155.23 | D6: =+D4-D5 -> 0 | E6: =+E4-E5 -> 0 | F6: =+F4-F5 -> 0 | G6: =+G4-G5 -> 0 | H6: =+H4-H5 -> 0 | I6: =+I4-I5 -> 0 | J6: =+J4-J5 -> 0 | ... N6: =+N4-N5 -> 0 | O6: =SUM(C6:N6) -> -4155.23
B7: saldo acumulado | C7: =+C6 -> -4155.23 | D7: =+C7+D6 -> -4155.23 | E7: =+D7+E6 -> -4155.23 | F7: =+E7+F6 -> -4155.23 | G7: =+F7+G6 -> -4155.23 | H7: =+G7+H6 -> -4155.23 | I7: =+H7+I6 -> -4155.23 | J7: =+I7+J6 -> -4155.23 | K7: =+J7+K6 -> -4155.23 | ... N7: =+M7+N6 -> -4155.23
B14: Etiquetas de fila | C14: Suma de valor
B15: salario
B16: feb | C16: 10818.92
B17: Total salario | C17: 10818.92
B18: Total general | C18: 10818.92
B42: Etiquetas de fila | C42: Suma de valor
B43: FEB | C43: 22817.85
B44: Total general | C44: 22817.85
F58: =+GETPIVOTDATA("valor",$B$14)-GETPIVOTDATA("valor",$B$42) -> -11998.93

Sheet tabulador
A1: lim.inferior | B1: lim.superior | C1: c.f | D1: %
A2: 0.01 | B2: 25000 | C2: 0 | D2: 1
A3: 25000.01 | B3: 50000 | C3: 0 | D3: 1.1
A4: 50000.01 | B4: 83333.33 | C4: 0 | D4: 1.5
A5: 83333.34 | B5: 208333.33 | C5: 0 | D5: 2
A6: 208333.34 | B6: 3500000 | C6: 0 | D6: 2.5
A7: 3500000 | B7: En adelante | C7: 0 | D7: 2.5

Sheet Gastos captura
A1: Gastos — Captura (manual o XML)
A2: Agrega los renglones/conceptos que necesites. Marca el Mes (1-12), la Categoria (Basico/Lujo/Ahorro), el Importe y el Origen. | H2: Resumen por categoria
H3: Mes: | I3: 1
A4: Mes | B4: Categoria | C4: Concepto | D4: Importe | E4: Origen
B5: Basico | C5: Renta / Hipoteca | D5: 0 | E5: Manual | H5: Categoria | I5: Monto | J5: % real | K5: Meta
B6: Basico | C6: Agua (CESPT) | D6: 0 | E6: Manual | H6: Basico | I6: =SUMIFS(Gastos[Importe],Gastos[Categoria],"Basico",Gastos[Mes],$I$3) | J6: =IFERROR(I6/$I$9,0) | K6: 0.5
B7: Basico | C7: Luz (CFE) | D7: 0 | E7: Manual | H7: Lujo | I7: =SUMIFS(Gastos[Importe],Gastos[Categoria],"Lujo",Gastos[Mes],$I$3) | J7: =IFERROR(I7/$I$9,0) | K7: 0.2
B8: Basico | C8: Gas | D8: 0 | E8: Manual | H8: Ahorro | I8: =SUMIFS(Gastos[Importe],Gastos[Categoria],"Ahorro",Gastos[Mes],$I$3) | J8: =IFERROR(I8/$I$9,0) | K8: 0.3
B9: Basico | C9: Internet | D9: 0 | E9: Manual | H9: TOTAL | I9: =SUM(I6:I8)
B10: Basico | C10: Telefono / Recargas | D10: 0 | E10: Manual
B11: Basico | C11: Mantenimiento privada | D11: 0 | E11: Manual
B12: Basico | C12: Predial | D12: 0 | E12: Manual
B13: Basico | C13: Despensa / Supermercado | D13: 0 | E13: Manual
B14: Basico | C14: Mercado | D14: 0 | E14: Manual
B15: Basico | C15: Transporte / Pasajes | D15: 0 | E15: Manual
B16: Basico | C16: Salud / Medicamentos | D16: 0 | E16: Manual
B17: Basico | C17: Escuela / Colegiaturas | D17: 0 | E17: Manual
B18: Lujo | C18: Restaurantes / Comidas | D18: 0 | E18: Manual
B19: Lujo | C19: Cine / Entretenimiento | D19: 0 | E19: Manual
B20: Lujo | C20: Ropa / Cosmeticos | D20: 0 | E20: Manual
B21: Lujo | C21: Libros / Cafe / Golosinas | D21: 0 | E21: Manual
... B28: Ahorro | C28: Ahorro / Fondo emergencia | D28: 0 | E28: Manual
